<?xml version="1.0"?>


<robot xmlns:xacro="https://wiki.ros.org/xacro">

    <xacro:property name="LINK1_MASS" value="0.1" />
    <xacro:property name="LINK2_MASS" value="0.1" />
    <xacro:property name="LINK3_MASS" value="0.1" />
    <xacro:property name="LINK4_MASS" value="0.1" />
    <xacro:property name="LINK_EE_MASS" value="0.1" />


    <link name="link1">
        <visual>
            <geometry>
                <cylinder radius="0.05" length="0.2" />
            </geometry>
            <material name="orange" />
        </visual>
        <inertial>
            <mass value="0.1" />
            <inertia ixx="0.001" ixy="0" ixz="0" iyy="0.001" iyz="0" izz="0.001" />
        </inertial>
    </link>


    <link name="link2">
        <visual>
            <origin xyz="0 0 0.25" />
            <geometry>
                <box size="0.05 0.05 0.5" />
            </geometry>
            <material name="yellow" />
        </visual>
        <inertial>
            <mass value="0.1" />
            <inertia ixx="0.001" ixy="0" ixz="0" iyy="0.001" iyz="0" izz="0.001" />
        </inertial>
    </link>

    <joint name="joint2" type="revolute">
        <parent link="link1" />
        <child link="link2" />
        <origin xyz="0 0 0.1" />
        <axis xyz="0 1 0" />
        <limit lower="-1.57" upper="1.57" effort="500" velocity="1" />
    </joint>

    <link name="link3">
        <visual>
            <origin xyz="0 0 0.2" />
            <geometry>
                <box size="0.04 0.04 0.4" />
            </geometry>
            <material name="orange" />
        </visual>
        <inertial>
            <mass value="0.1" />
            <inertia ixx="0.001" ixy="0" ixz="0" iyy="0.001" iyz="0" izz="0.001" />
        </inertial>
    </link>
    <joint name="joint3" type="revolute">
        <parent link="link2" />
        <child link="link3" />
        <origin xyz="0 0 0.5" />
        <axis xyz="0 1 0" />
        <limit lower="-2.5" upper="2.5" effort="200" velocity="1" />
    </joint>

    <link name="link4">
        <visual>
            <geometry>
                <box size="0.03 0.03 0.1" />
            </geometry>
            <material name="yellow" />
        </visual>
        <inertial>
            <mass value="0.01" />
            <inertia ixx="0.0001" ixy="0" ixz="0" iyy="0.0001" iyz="0" izz="0.0001" />
        </inertial>
    </link>
    <joint name="joint4" type="revolute">
        <parent link="link3" />
        <child link="link4" />
        <origin xyz="0 0 0.4" />
        <axis xyz="0 1 0" />
        <limit lower="-1.57" upper="1.57" effort="100" velocity="1" />
    </joint>

    <link name="end_effector">
        <visual>
            <geometry>
                <box size="0.1 0.05 0.02" />
            </geometry>
            <material name="blue" />
        </visual>
        <inertial>
            <mass value="0.01" />
            <inertia ixx="0.0001" ixy="0" ixz="0" iyy="0.0001" iyz="0" izz="0.0001" />
        </inertial>
    </link>
    <joint name="joint5" type="revolute">
        <parent link="link4" />
        <child link="end_effector" />
        <origin xyz="0 0 0.05" />
        <axis xyz="0 0 1" />
        <limit lower="-3.14" upper="3.14" effort="50" velocity="1" />
    </joint>
</robot>