<?xml version="1.0"?>


<robot name="usenav_arm" xmlns:xacro="https://wiki.ros.org/xacro">

    <xacro:include filename="../common_properties.xacro" />
    <xacro:include filename="./arm.xacro" />
    <xacro:include filename="./arm_gz.xacro" />
    
    
    <link name="base_footprint" />
    
    <joint name="base_joint" type="fixed">
        <parent link="base_footprint" />
        <child link="base_link" />
        <origin xyz="0.0 0.0 0.0" rpy="0.0 0.0 0.0"/>
    </joint>
    
    <link name="base_link" />
    
    <joint name="joint1" type="revolute">
        <parent link="base_footprint" />
        <child link="link1" />
        <origin xyz="0.0 0.0 0.0" rpy="0.0 0.0 0.0"/>
        <axis xyz="0 0 1" />
        <limit lower="-3.14" upper="3.14" effort="100" velocity="1" />
    </joint>
    

</robot>